Workbook
Name newRating: ratingScore!$A$1:$E$6
Name newRating1: ratingScore!$B$2:$E$6
Name rating: [1]ratingScore!$B$2:$E$6
Name rating: ratingScore!$B$2:$E$6
Name ratingDesc: #REF!
Name RatingGrade: #REF!
Name status: reference!$A$1:$A$4

Sheet reference
A1: Not Started Yet
A2: Completed
A3: In Progress

Sheet Rating
A1: Ranking
A3: Not Applicable | C3: 0 | D3: 69 | E3: 0 | G3: Failed
A4: Strongly Disagree | C4: 70 | D4: 74 | E4: 1 | F4: Not yet capable
A5: Disagree | C5: 75 | D5: 84 | E5: 2 | F5: Some capability and significant improvement | G5: Passed
A6: Neutral | C6: 85 | D6: 88 | E6: 3 | F6: Some capability and and needs improvement
A7: Agree | C7: 89 | D7: 94 | E7: 4 | F7: Capable
A8: Strongly Agree | C8: 100 | D8: 95 | E8: 5 | F8: Expert
A12: Proficiency Level
A13: Limited | B13: 0 | C13: 49 | D13: L | E13: Limited, demonstrated a little knowledge and usually exploring the content
A14: Developing | B14: 50 | C14: 99 | D14: D | E14: Developing, demonstrated a know;edge in early stages
A15: Established | B15: 100 | C15: 149 | D15: E | E15: Established, demonstrated a better and the scores top on this category
A16: Superior | B16: 150 | C16: 200 | D16: S | E16: Superior, demonstrated knowledge better than almost all other learners

Sheet Performance Summary
A1: SSCGI Bootcamper Performance Evaluation Result Summary
D2: =#REF! -> #REF! | G2: ADJECTIVAL RATE | H2: RECOMMENDATION | J2: RATIONALE
B3: Employee Name :
B4: Department / Group : | D4: =#REF! -> #REF! | G4: =#REF! -> #REF! | H4: =#REF! -> #REF! | J4: With his 92% demonstrated a strong alignment with the core competencies required for a Systems Development (SysDev) role. His exceptional technical proficiency, problem-solving ability, and collaboration skills make him a standout candidate. His consistent high scores across multiple evaluation criteria, including technical skills (24%), problem-solving (24%), and collaboration (14%), showcase his readiness for complex development tasks and teamwork environments.
B5: Nickname : | D5: =#REF! -> #REF!
B6: Date Attended : | D6: =#REF! -> #REF!
B7: Covered Period : | D7: =#REF! -> #REF!
B8: Project Manager : | D8: =#REF! -> #REF!
F10: FEEDBACK FORM
D11: TARGET | E11: ACTUAL | F11: STRENGTH | I11: FOR IMPROVEMENTS | K11: REFLECTIONS
K12: Bootcamper's approach on what, why or how to maintain the strength and improve areas identified.
B13: A | C13: TECHNICAL SKILLS | D13: 0.25 | E13: =#REF! -> #REF! | F13: He demontrates a good performance in technical areas in the field of data structure and algorithms and a logical or systemative problem-solving process. He has an understaing in best practices and error handling | K13: Strength To maintain my strength, I’ll continue building on my technical competence by staying up to date with industry trends and deepening your knowledge by continuously studying the concepts I am good at. Keep completing tasks consistently, focus on refining problemsolving abilities, and take time to review and improve my work. Engaging in ongoing learning and applying new concepts will also help me stay sharp. • Areas to improve To improve my weaknesses, I'll start actively participating in team discussions and collaborating with others. Look for opportunities to contribute ideas or ask questions to show engagement. To enhance my proactivity, I take the initiative to seek out new learning opportunities, such as exploring new tools, and sharing insights with the team. By focusing on these areas, I'll be able to build stronger teamwork skills and enhance my overall performance.
B14: B | C14: PROBLEM-SOLVING SKILLS | D14: 0.25 | E14: =#REF! -> #REF! | F14: He understands user requirements and deliver functional, reliable feautres with enhanced UI/UX scoring near perfect of 24% out of 25% | I14: He needs slight improvement in UI/UX or front-end applications.
B15: C | C15: COMMUNICATION SKILLS | D15: 0.15 | E15: =#REF! -> #REF! | F15: Active in class participation can explain the logic of his code. | I15: While proficient (3% out of 4%), further attention to clean code standards, such as consistent formatting, commenting, and optimization techniques, would strengthen the overall output quality.
B16: D | C16: COLLABORATION AND PROFESSIONALISM | D16: 0.15 | E16: =#REF! -> #REF! | F16: He shows collaboration and camaraderie by teaching and sharing his knowledge to his peers
B17: E | C17: FORMATIVE ASSESSMENT | D17: 0.2 | E17: =#REF! -> #REF!

Sheet Regularization Endorsement
J2: HRMFORM-021-04-REV000
C4: PERFORMANCE EVALUATION REPORT
B6: Employee Name: | I6: Type of Evaluation:
B7: Position Title: | I7: þ | J7: Regularization
B8: Department: | I8: o | J8: Annual
B9: Evaluation Period: | I9: o | J9: Promotion
I10: o | J10: Warning
I11: o | J11: Extension of Probationary Contract
B13: SCORING PER CATEGORY:
B15: PERFORMANCE REVIEW | E15: Scoring | G15: DESCRIPTION:
B16: Project Execution | E16: ='Performance Evaluation'!F19 -> 0.11825 | G16: Meets the baseline expectations.
B17: Compliance
B18: Efficiency and Organizational Development
B19: Total | E19: =E16 -> 0.11825
B21: BEHAVIORAL EVALUATION | E21: Scoring | G21: INTERPRETATION:
B22: Basic Job Functions | E22: ='Performance Evaluation'!F20 -> 0
B23: Professional & Customer Service
B24: Managerial Function
B25: Total | E25: =E22 -> 0
B27: FINAL RATING | E27: =E19+E25 -> 0.11825
B29: OTHER RECOMMENDING DETAILS:
G30: VERIFIED BY:
B31: Current Employment Status: | D31: Trainee
B32: Percentage Increase (if any):
B33: Rate Based on Evaluation: | G33: MS. RUBYLYN Q. MALUBAY
B34: Current Job Title: | D34: Software Developer I | G34: Human Resources Manager
B35: Last Salary Adjustment:
G36: NOTED BY:
G39: MR. GABRIEL MCJOHN MAMARIL
G40: Manager - Research and Develoipment
G42: MS. FLORDELIZA R. FERNANDEZ
G43: Technical Trainer - Consultant
G45: APPROVED BY:
G48: MS. DIANNE CAROL A. DE LEON
G49: Vice President – Technical and Business Operation
B50: To the Employee: Signature indicates receipt of the evaluation
G55: RECEIVED BY:
G57: MARQUILLERO, RUSELL JOHN
G58: Employee Name

Sheet Performance Evaluation
B2: EMPLOYEE PERFORMANCE EVALUATION RESULT SUMMARY
C4: DEPARTMENT / GROUP | D4: : | E4: RESEARCH AND DEVELOPMENT | G4: ADJECTIVAL RATE | H4: INTERPRETATION
C5: EMMPLOYEE NAME | D5: : | E5: MARQUILLERO, RUSELL JOHN
C6: DATE HIRED | D6: : | E6: 45898
C7: COVERED PERIOD | D7: : | E7: REGULARIZATION
C8: SUPERVISOR | D8: : | E8: FLORDELIZA FERNANDEZ
F10: FEEBACK FORM
D11: TARGET | E11: ACTUAL | F11: STRENGTH | H11: FOR IMPROVEMENTS
B12: A | C12: EMPLOYEE ENGAGEMENT | D12: 0.25 | E12: =(Dashboard!F14*0.5)+(Dashboard!F26*0.5) -> 0.11825
B13: B | C13: PRODUCTIVITY | D13: 0.2 | E13: =(Dashboard!F15*0.5)+(Dashboard!F27*0.5) -> 0
B14: C | C14: WORK QUALITY | D14: 0.15 | E14: =(Dashboard!F16*0.5)+(Dashboard!F28*0.5) -> 0
B15: D | C15: CUSTOMER SATISFACTION / SERVICE LEVEL COMMITMENT | D15: 0.15 | E15: =(Dashboard!F17*0.5)+(Dashboard!F29*0.5) -> 0
B16: E | C16: SELF IMPROVEMENT (TRAININGS) | D16: 0.05 | E16: 0
B17: F | C17: COMPLIANCE | D17: 0.05 | E17: 0
B18: G | C18: ETHICS AND VALUES | D18: 0.15 | E18: 0
D19: 1 | E19: =F19+F20 -> 0.11825 | F19: =SUM(E12:E16) -> 0.11825
F20: =SUM(E17:E18) -> 0
B21: I hereby certify that I have been informed of my performance rankings. The rankings and feedback provided in this review have been thoroughly discussed with me by my supervisor, ensuring that I fully understand the evaluation results. I also acknowledge that I have successfully completed the bootcamp training. Additionally, I have reviewed and provided my own comments on the evaluation.
C24: EMPLOYEE ACKNOWLEDGEMENT | G24: SUPERVISOR ACKNOWLEDGEMENT
C25: Signature: | G25: Signature:
C26: Name: | G26: Name:
C27: Date: | G27: Date:

Sheet Dashboard
A1: PERFORMANCE EVALUATION RESULT SUMMARY
B3: Name | D3: RUSELL JOHN MARQUILLERA | G3: RATING | I3: ADJECTIVAL RATE | K3: INTERPRETATION
B4: Position | D4: BOOTCAMPER | G4: =(G12*0.5)+(G24*0.5) -> 0.23045 | I4: =VLOOKUP(G4,newRating1, 3, TRUE) -> POOR | K4: =VLOOKUP(G4, newRating1, 4, TRUE) -> Consistently failed to expectations.
B5: Division/Group | D5: SSCGI BOOTCAMP
C6: Covered Period | D6: AUGUST - FEBRUARY 2026
B7: Endorsed Department | D7: RESEARCH AND DEVELOPMENT
B8: Trainer | D8: FLORDELIZA FERNANDEZ
B10: BOOTCAMPER SCORECARD
G11: RATING | I11: ADJECTIVAL RATE | K11: INTERPRETATION
G12: =+F14+F15+F16+F17+F18+F19+F20 -> 0.4609 | I12: =VLOOKUP(G12,ratingScore!B2:E6,3,TRUE) -> POOR | K12: =VLOOKUP(G12,ratingScore!B2:E6,4,TRUE) -> Consistently failed to expectations.
B13: CRITERIA | E13: TARGET | F13: ACTUAL | G13: STRENGTH | L13: FOR IMPROVEMENTS
B14: A | C14: EMPLOYEE ENGAGEMENT | E14: 0.25 | F14: =BootcampEndorsementScoreCard!E12 -> 0.2365
B15: B | C15: PRODUCTIVITY | E15: 0.2 | F15: =BootcampEndorsementScoreCard!E13 -> 0
B16: C | C16: WORK QUALITY | E16: 0.15 | F16: =BootcampEndorsementScoreCard!E14 -> 0
B17: D | C17: CUSTOMER SATISFACTION/SERVICE LEVEL COMMITMENT | E17: 0.1 | F17: =BootcampEndorsementScoreCard!E15 -> 0
B18: E | C18: SELF IMPROVEMENT (TRAININGS) | E18: 0.1 | F18: =BootcampEndorsementScoreCard!E16 -> 0.04
B19: F | C19: COMPLIANCE | E19: 0.1 | F19: =BootcampEndorsementScoreCard!E17 -> 0.1
B20: G | C20: ETHICS AND VALUES | E20: 0.1 | F20: =BootcampEndorsementScoreCard!E18 -> 0.0844
B22: ENDORSED TRAINEE SCORECARD
G23: RATING | I23: ADJECTIVAL RATE | K23: INTERPRETATION
G24: =+F26+F27+F28+F29+F30+F31+F32 -> 0 | I24: =VLOOKUP(G24,newRating1, 3, TRUE) -> POOR | K24: =VLOOKUP(G24,newRating1,4,TRUE) -> Consistently failed to expectations.
B25: CRITERIA | E25: TARGET | F25: ACTUAL | G25: STRENGTH | L25: FOR IMPROVEMENTS
B26: A | C26: EMPLOYEE ENGAGEMENT | E26: =BootcampEndorsementScoreCard!D12 -> 0.25 | F26: ='Part 1 Evaluation'!E12 -> 0
B27: B | C27: PRODUCTIVITY | E27: =BootcampEndorsementScoreCard!D13 -> 0.2 | F27: ='Part 1 Evaluation'!E13 -> 0
B28: C | C28: WORK QUALITY | E28: =BootcampEndorsementScoreCard!D14 -> 0.15 | F28: ='Part 1 Evaluation'!E14 -> 0
B29: D | C29: CUSTOMER SATISFACTION/SERVICE LEVEL COMMITMENT | E29: =BootcampEndorsementScoreCard!D15 -> 0.1 | F29: ='Part 1 Evaluation'!E15 -> 0
B30: E | C30: SELF IMPROVEMENT (TRAININGS) | E30: =BootcampEndorsementScoreCard!D16 -> 0.1 | F30: ='Part 1 Evaluation'!E16 -> 0
B31: F | C31: COMPLIANCE | E31: =BootcampEndorsementScoreCard!D17 -> 0.1 | F31: ='Part 1 Evaluation'!E17 -> 0
B32: G | C32: ETHICS AND VALUES | E32: =BootcampEndorsementScoreCard!D18 -> 0.1 | F32: ='Part 1 Evaluation'!E18 -> 0

Sheet Part 1 Evaluation
B2: EMPLOYEE PERFORMANCE EVALUATION RESULT SUMMARY
C4: DEPARTMENT / GROUP | D4: : | E4: RESEARCH AND DEVELOPMENT | G4: ADJECTIVAL RATE | H4: INTERPRETATION
C5: EMMPLOYEE NAME | D5: : | E5: MARQUILLERO, RUSELL JOHN
C6: DATE HIRED | D6: : | E6: 45898
C7: COVERED PERIOD | D7: : | E7: REGULARIZATION
C8: SUPERVISOR | D8: : | E8: FLORDELIZA FERNANDEZ
F10: FEEBACK FORM
D11: TARGET | E11: ACTUAL | F11: STRENGTH | H11: FOR IMPROVEMENTS
B12: A | C12: EMPLOYEE ENGAGEMENT | D12: 0.25 | E12: ='Technical Evaluation'!I18 -> 0
B13: B | C13: PRODUCTIVITY | D13: ='Technical Evaluation'!I21 -> 0 | E13: 0
B14: C | C14: WORK QUALITY | D14: 0.15 | E14: ='Technical Evaluation'!I24 -> 0
B15: D | C15: CUSTOMER SATISFACTION / SERVICE LEVEL COMMITMENT | D15: 0.15 | E15: ='Technical Evaluation'!I28 -> 0
B16: E | C16: SELF IMPROVEMENT (TRAININGS) | D16: 0.05 | E16: ='Technical Evaluation'!I31 -> 0
B17: F | C17: COMPLIANCE | D17: 0.05 | E17: ='Technical Evaluation'!I35 -> 0
B18: G | C18: ETHICS AND VALUES | D18: 0.15 | E18: ='Technical Evaluation'!I40 -> 0
D19: 1 | E19: =SUM(E12:E16) -> 0 | F19: =E17+E18 -> 0
B21: I hereby certify that I have been informed of my performance rankings. The rankings and feedback provided in this review have been thoroughly discussed with me by my supervisor, ensuring that I fully understand the evaluation results. I also acknowledge that I have successfully completed the bootcamp training. Additionally, I have reviewed and provided my own comments on the evaluation.
C24: EMPLOYEE ACKNOWLEDGEMENT | G24: SUPERVISOR ACKNOWLEDGEMENT
C25: Signature: | G25: Signature:
C26: Name: | G26: Name:
C27: Date: | G27: Date:

Sheet Technical Evaluation
B2: EMPLOYEE PERFORMANCE EVALUATION FORM
H3: ADJECTVAL RATING
C5: EMPLOYEE NAME: | D5: MARQUILLERO, JOHN RUSELL | E5: DEPARTMENT: | F5: RESEARCH AND DEVELOPMENT | H5: =+I18+I21+I24+I28+I31+I35+I40 -> 0
C6: DATE HIRED: | D6: 45898 | E6: COVERED PERIOD | F6: PROBATIONARY
C7: DESIGNATION: | D7: TRAINEE | E7: DATE REVIEWED | F7: 46063
C8: MANAGER/SUPERVISOR: | D8: FLORDELIZA FERNANDEZ
B11: ITEM # | C11: CRITERIA | D11: GOALS / TARGETS | E11: BASIS FOR SCORING | F11: RATE MATRIX | G11: WEIGHT | H11: MAX SCORE | I11: TOTAL % SCORE
B12: FUNCTIONAL AREA | G12: 1 | H12: 5 | I12: 0.74
B13: A | C13: EMPLOYEE ENGAGEMENT [25%] | G13: TARGET | H13: ACTUAL | I13: COMPUTED %
B15: 1 | C15: Tasks completed as stated in the WAS | D15: Taskes handled should be completed based on the weekly assigned activies | E15: Tasks completed/submitted and checked by the client/supervisor. Basis is the CIC and Inia Projects | F15: - Rate to be based on the following project delays percentage (%) 0% = 5 < 20% = 4 < 40% = 3 < 60% = 2 < 80% = 1 | G15: 0.1 | I15: =(H15/$H$12)*G15 -> 0
B16: 2 | C16: Milestones Completed on Time | D16: Project Milestones (Terms of Payment) should be completed as breakdown/describe in the approved project schedules at the commencement of the project. | E16: - Approved Project Schedule with the Customer w/ the project milestone schedule indicators; Basis is the CIC and Inia Projects | F16: - Rate to be based on the following project delays percentage (%) 0% = 5 < 20% = 4 < 40% = 3 < 60% = 2 < 80% = 1 | G16: 0.08 | I16: =(H16/$H$12)*G16 -> 0
B17: 3 | C17: Number of Customer Complaints | D17: Avoid any customer escalation and/or complaints. Project team should be able to manage, mitigate any issues before it gets escalated or before it gets complained | E17: - Number of events where a complaint / escalation was received from a client either in any form of communication. Issue Defect / Tickets is excluded. Basis is the CIC and Inia Projects | F17: - Ratings shall be based on the following number of events were request for project rebaseline has been requested; 0 Event = 5 1st to 2nd Event = 4 3rd to 4th Event = 3 4th to 5th Event = 2 6th & up Event = 1 | G17: 0.07 | I17: =(H17/$H$12)*G17 -> 0
F18: TOTAL | G18: =+G15+G16+G17 -> 0.25 | H18: =+H15+H16+H17 -> 0 | I18: =SUM(I15:I17) -> 0
B19: B | C19: PRODUCTIVITY [20%] | G19: TARGET | H19: ACTUAL | I19: COMPUTED %
B20: 9 | C20: Number of Action Listed vs. Completed | D20: To ensure members time are well spent | E20: - Basis shall be the task list score card (refer to members score card sheet) and weekly tasks list calendar (refer to members task list calendar) Basis is the CIC and Inia Projects | F20: Based on actual computed score. Rate shall be based on the following matrix; 100% = 5 >80% = 4 >60% = 3 >40% = 2 >20% = 1 10% = 0 | G20: 0.2 | I20: =(H20/$H$12)*G20 -> 0
F21: TOTAL | G21: =G20 -> 0.2 | H21: =H20 -> 0 | I21: =I20 -> 0
B22: C | C22: WORK OUTPUT QUALITY [15%] | G22: TARGET | H22: ACTUAL | I22: COMPUTED %
B23: 10 | C23: Number of Errors and/or Bug reported | D23: To ensure quality of members output is given priority | E23: - Basis shall be the Issue register produced during the SIT and/or UAT and Production Phase of the project covering the warranty Phase Basis is the CIC and Inia Projects IR | F23: Based on % errors or bugs/Number of Test Cases > 30% = 1 < 30% = 2 < 25% = 3 < 20% = 4 <10% = 5 | G23: 0.15 | I23: =(H23/$H$12)*G23 -> 0
F24: TOTAL | G24: =G23 -> 0.15 | H24: =H23 -> 0 | I24: =I23 -> 0
B25: D | C25: CUSTOMER SATISFACTION / SERVICE LEVEL COMMITMENT [15%] | G25: TARGET | H25: ACTUAL | I25: COMPUTED %
B26: 11 | C26: Number of Tickets vs. Resolved | D26: To ensure that service level commitment is prioritize and given importance | E26: - Basis is the CIC and Inia Projects IR Report | F26: Based on actual computed score. Rate shall be based on the following matrix; 100% = 5 > 80% = 4 > 60% = 3 > 40% = 2 > 20% = 1 | G26: 0.08 | I26: =(H26/$H$12)*G26 -> 0
B27: 12 | C27: Abandon Rate | D27: To ensure that all reported tickets are attended | E27: - Basis is the CIC and Inia Projects IR Report | F27: Based on % computed over total # of assigned tickets. Rate to be based on the ff percentage (%) > 60% =1 < 60% = 2 < 50% = 3 < 25% = 4 < 10% = 5 | G27: 0.07 | I27: =(H27/$H$12)*G27 -> 0
F28: TOTAL | G28: =G26+G27 -> 0.15 | H28: =+H26+H27 -> 0 | I28: =+I26+I27 -> 0
B29: E | C29: SELF IMPROVEMENT / TRAININGS [5%] | G29: TARGET | H29: ACTUAL | I29: COMPUTED %
B30: 14 | C30: Number Trainings Hours vs. Planned | D30: To promote members development and help members build on strengths and address deficiencies identified in their performance reviews. To encourage members discover areas in which they could use additional educational opportunities and support. | E30: - Based on total hours of training / sessions / seminars required vs actual attended [Based on # of trainings attended/Trainings scheduled] | F30: Based on actual computed score. Rate shall be based on the following matrix; 100% = 5 >80% = 4 >60% = 3 >40% = 2 >20% = 1 | G30: 0.05 | I30: =(H30/$H$12)*G30 -> 0
F31: TOTAL | G31: =G30 -> 0.05 | H31: =H30 -> 0 | I31: =I30 -> 0
B32: F | C32: COMPLIANCE [5%] | G32: TARGET | H32: ACTUAL | I32: COMPUTED %
B33: 15 | C33: Attendance | D33: To ensure that members are present and arriving at work on time and in accordance with the policies and procedure. This promotes and ensure business operation continuity. | E33: Leaves are filed according to policy | F33: 0 infraction = 5 1 infraction = 4 > 1 infraction = 1 | G33: 0.03 | I33: =(H33/$H$12)*G33 -> 0
B34: 16 | C34: Policy | D34: To ensure that employees and the organization as a whole abide by internal rules of conduct and external rules and regulations. | E34: No recorded policy violation | F34: 0 infraction = 5 1 infraction = 4 > 1 infraction = 1 | G34: 0.02 | I34: =(H34/$H$12)*G34 -> 0
F35: TOTAL | G35: =+G33+G34 -> 0.05 | H35: =+H33+H34 -> 0 | I35: =+I33+I34 -> 0
B36: ETHICS AND VALUES | G36: TARGET | H36: MAX SCORE | I36: TOTAL % SCORE
B37: G | C37: BEHAVIORAL | G37: 0.15 | H37: 0.05 | I37: 0
G38: TARGET | H38: ACTUAL | I38: COMPUTED %
B39: 17 | C39: Interpersonal Relations / Behavior | E39: - Score based on the result of FORM B | F39: Rate shall be based on the actual computed score in FORM B | G39: 0.15 | I39: =(H39/$H$12)*G39 -> 0
F40: TOTAL | G40: =G39 -> 0.15 | H40: =H39 -> 0 | I40: =I39 -> 0
F41: GRAND TOTAL
B43: PERFORMANCE REVIEW DISCUSSION AND SIGN OFF
G44: HR REPRESENTATIVE
C45: EMPLOYEE ACKNOWLEDGEMENT | E45: SUPERVISOR ACKNOWLEDGEMENT
C46: Signature | E46: Signature
...

Sheet BootcampEndorsementScoreCard
B2: EMPLOYEE PERFORMANCE EVALUATION RESULT SUMMARY
C4: DEPARTMENT / GROUP | G4: ADJECTIVAL RATE | H4: INTERPRETATION
C5: EMMPLOYEE NAME | G5: =+E12+E13+E14+E15+E16+E17+E18 -> 0.4609 | H5: =VLOOKUP(G5,ratingScore!B2:E6,4,TRUE) -> Consistently failed to expectations.
C6: DATE HIRED
C7: COVERED PERIOD
C8: SUPERVISOR
F10: FEEBACK FORM
D11: TARGET | E11: COMPUTED | F11: STRENGTH | H11: FOR IMPROVEMENTS
B12: A | C12: EMPLOYEE ENGAGEMENT | D12: 0.25 | E12: =BootCampScoreCard!O19 -> 0.2365
B13: B | C13: PRODUCTIVITY | D13: 0.2 | E13: =BootCampScoreCard!O25 -> 0 | F13: Actively participated in team activities, showing strong collaboration and problem-solving skills.
B14: C | C14: WORK QUALITY | D14: 0.15 | E14: =BootCampScoreCard!O30 -> 0 | H14: While generally strong, attention to detail can be improved to ensure error-free work in every task.
B15: D | C15: CUSTOMER SATISFACTION / SERVICE LEVEL COMMITMENT | D15: 0.1 | E15: =BootCampScoreCard!O34 -> 0 | F15: Demonstrated good leadership qualities by leading by example in group activities. | H15: While deadlines are met, further engagement in offering assistance and feedback could improve customer service levels and teamwork.
B16: E | C16: SELF IMPROVEMENT (TRAININGS) | D16: 0.1 | E16: =BootCampScoreCard!O38 -> 0.04
B17: F | C17: COMPLIANCE | D17: 0.1 | E17: =BootCampScoreCard!O42 -> 0.1
B18: G | C18: ETHICS AND VALUES | D18: 0.1 | E18: =BootCampScoreCard!O45 -> 0.0844
D19: =SUM(D12:D18) -> 1 | E19: =SUM(E12:E18) -> 0.4609
B21: I hereby certify that I have been advised of my performance rankings. The rankings and comments in this review have been discussed and explained to me by my supervisor. My own comments are as follows:
B24: EMPLOYEE ACKNOWLEDGEMENT | G24: SUPERVISOR ACKNOWLEDGEMENT
B25: Signature: | G25: Signature:
B26: Name: | G26: Name:
B27: Date: | G27: Date:

Sheet BootCampScoreCard
A1: PERFORMANCE EVALUATION RESULT SUMMARY
B3: Employee Name | G3: RATING | I3: ADJECTIVAL RATE | K3: INTERPRETATION
B4: Department | G4: =O13 -> 0.4609 | I4: =VLOOKUP(G4,rating, 3, TRUE) -> POOR | K4: =VLOOKUP(G4, rating, 4, TRUE) -> Consistently failed to expectations.
B5: Date Attended
B6: Covered Period
B7: Date Edorsed/Target Joined the Team
B8: Trainer/Facilitator
B11: # | C11: CRITERIA | E11: GOALS/TARGET | H11: BASIS SCORING | K11: RATE MATRIX | M11: WEIGHT | N11: MAX | O11: TOTAL
M12: (%) | N12: SCORE | O12: SCORE
M13: =+M19+M25+M30+M34+M38+M42+M45 -> 1 | N13: 5 | O13: =+O19+O25+O30+O34+O38+O42+O45 -> 0.4609
B14: A | C14: EMPLOYEE ENGAGEMENT [25%] | E14: Active participation in team activities and course discussion | K14: 0.25 | M14: TARGET | N14: ACTUAL | O14: COMPUTED
B15: 1 | C15: Teamwork and Collaboration | E15: 100% participation in team activities and problem-solving | H15: Rate based on active participation in team discussion, collaboration and problem-solving during lessons | K15: Based on actual computed score. Rate shall be based on the following matrix: 100% = 5 >80% = 4 >60% = 3 >40% = 2 >20% = 1 10% = 0 | M15: 0.07 | N15: =ScoreBoard!E3 -> 5 | O15: =(N15/$N$13)*M15 -> 0.07
B16: 2 | C16: Problem-solving and Understanding the Requirements | E16: Takes ownership of tasks and contributes innovative solutions | H16: Evaluate proactive problem-solving abilities and ownership shown in quizzes and assignments. | M16: 0.06 | N16: =ScoreBoard!G3 -> 4.375 | O16: =(N16/$N$13)*M16 -> 0.0525
B17: 3 | C17: Communication Skills | E17: Clear and concise communication with team members | H17: Rate communication clarity in discussions, recitations and presentations. | M17: 0.06 | N17: =ScoreBoard!I3 -> 4.5 | O17: =(N17/$N$13)*M17 -> 0.054
B18: 4 | C18: Team Leadership | E18: Lead by example in group activities | H18: Rate the leadership qualities during team activities and group presentations | M18: 0.06 | N18: =ScoreBoard!K3 -> 5 | O18: =(N18/$N$13)*M18 -> 0.06
M19: =+M15+M16+M17+M18 -> 0.25 | N19: =+N15+N16+N17+N18 -> 18.875 | O19: =+O15+O16+O17+O18 -> 0.2365
B20: B | C20: PRODUCTIVITY [20%] | E20: Meet deadlines and deliver high-quality work on time | K20: 0.2 | M20: TARGET | N20: ACTUAL | O20: COMPUTED
B21: 5 | C21: Efficiency and Output Quality | E21: High-qualiy, accurate and timely output of work. | H21: Rate based on timely submissions | K21: Based on actual computed score. Rate shall be based on the following matrix: 100% = 5 >80% = 4 >60% = 3 >40% = 2 >20% = 1 10% = 0 | M21: 0.05 | N21: =ScoreBoard!N3 -> 0 | O21: =(N21/$N$13)*M21 -> 0
B22: 6 | C22: Adherence to Deadlines and Workload Management | E22: Complete tasks on time, meeting deadlines and quality expectations. | H22: Evaluate the ability to meet deadlines, submit assignments on time and manage workloads effectively. | M22: 0.05 | N22: =ScoreBoard!P3 -> 0 | O22: =(N22/$N$13)*M22 -> 0
B23: 7 | C23: Knowledge of Tools and Technologies | E23: Proficient in using relevant tools and technologies to complete tasks effectively | H23: Proficicncy and ability to apply tools | M23: 0.05 | N23: =ScoreBoard!R3 -> 0 | O23: =(N23/$N$13)*M23 -> 0
B24: 8 | C24: Problem-solving Ability | E24: Ability to solve problems effectively | H24: Evaluate the ability to meet deadlines, submit assignments on time and manage workloads effectively. | M24: 0.05 | N24: =ScoreBoard!T3 -> 0 | O24: =(N24/$N$13)*M24 -> 0
M25: =+M21+M22+M23+M24 -> 0.2 | N25: =+N21+N22+N23+N24 -> 0 | O25: =+O21+O22+O23+O24 -> 0
B26: C | C26: WORK QUALITY [15%] | E26: Attention to detail and high-quality output in all tasks. | K26: 0.15 | M26: TARGET | N26: ACTUAL | O26: COMPUTED
B27: 9 | C27: Attention to Detail | E27: Ensure high precision and thoroughness in completing tasks. | H27: Rate the task accuracy, precision and thoroughness | K27: Based on actual computed score. Rate shall be based on the following matrix: 100% = 5 >80% = 4 >60% = 3 >40% = 2 >20% = 1 10% = 0 | M27: 0.05 | N27: =ScoreBoard!W3 -> 0 | O27: =(N27/$N$13)*M27 -> 0
B28: 10 | C28: Quality of Work | E28: Deliver work with high quality and professionalism. | H28: Work is complete flawlessly with no errors and exceeds expectations in every eay with all requirements are met. | M28: 0.05 | N28: =ScoreBoard!Y3 -> 0 | O28: =(N28/$N$13)*M28 -> 0
B29: 11 | C29: Work Output | E29: Produce high-quality and error-free work outputs. | H29: Work is completed ahead of time with high quality, no errors and meets or exceeds expectations | M29: 0.05 | N29: =ScoreBoard!AA3 -> 0 | O29: =(N29/$N$13)*M29 -> 0
M30: =+M27+M28+M29 -> 0.15 | N30: =+N27+N28+N29 -> 0 | O30: =+O27+O28+O29 -> 0
B31: D | C31: CUSTOMER SATISFACTION/SERVICE LEVEL COMMITMENT [10%] | E31: Consistenlty meet deadlines and provide excellent service. | K31: 0.1 | M31: TARGET | N31: ACTUAL | O31: COMPUTED
B32: 12 | C32: Meets deadlines for assignments and course requirements | E32: Meet deadlines and deliver high-quality work on time | H32: Evaluates whether deadlines for tasks, assignments and projects were met consistently | K32: Based on actual computed score. Rate shall be based on the following matrix: 100% = 5 >80% = 4 >60% = 3 >40% = 2 >20% = 1 10% = 0 | M32: 0.05 | N32: =ScoreBoard!AD3 -> 0 | O32: =(N32/$N$13)*M32 -> 0
B33: 13 | C33: Actively engages with teammates during recitations or offering assistance and feedback | E33: Actively contributes and offers assistance | H33: Evaluate teamwork and communication in collaborative project and assignments. | M33: 0.05 | N33: =ScoreBoard!AF3 -> 0 | O33: =(N33/$N$13)*M33 -> 0
M34: =+M32+M33 -> 0.1 | N34: =+N32+N33 -> 0 | O34: =+O32+O33 -> 0
B35: E | C35: SELF-IMPROVEMENT [10%] | E35: Demonstrate continuous learning and growth | K35: 0.1 | M35: TARGET | N35: ACTUAL | O35: COMPUTED
B36: 14 | C36: Summative Assessment | E36: Actively seeks feedback and applies it improve | H36: Rate how the trainee engages in learning, respond to feedback and improves overtime. | K36: Based on actual computed score. Rate shall be based on the following matrix: 100% = 5 >80% = 4 >60% = 3 >40% = 2 >20% = 1 10% = 0 | M36: 0.08 | N36: =ScoreBoard!AI3 -> 2.5 | O36: =(N36/$N$13)*M36 -> 0.04
B37: 15 | C37: Grooming and Attire | E37: Actively seeks feedback and applies it improve | H37: Rate how the trainee engages in learning, respond to feedback and improves overtime. | M37: 0.02 | N37: =ScoreBoard!AK3 -> 0 | O37: =(N37/$N$13)*M37 -> 0
M38: =M36+M37 -> 0.1 | N38: =N36+N37 -> 2.5 | O38: =O36+O37 -> 0.04
B39: F | C39: COMPLIANCE [10%] | E39: Adhere to all compliance guidelines and policies | K39: 0.05 | M39: TARGET | N39: ACTUAL | O39: COMPUTED
B40: 16 | C40: Adherence to the policy and guidelines of bootcamp and SSGCI | E40: Fully adheres to all policies and guidelines. | H40: Assess how well the trainees follow the policies, guidelines and the general conduct | K40: Based on actual computed score. Rate shall be based on the following matrix: 100% = 5 >80% = 4 >60% = 3 >40% = 2 >20% = 1 10% = 0 | M40: 0.05 | N40: 5 | O40: =(N40/$N$13)*M40 -> 0.05
B41: 17 | C41: Punctuality and attendance | E41: Evaluate the attendance. | H41: Evaluate the attendance. | M41: 0.05 | N41: 5 | O41: =(N41/$N$13)*M41 -> 0.05
M42: =+M40+M41 -> 0.1 | N42: =+N40+N41 -> 10 | O42: =+O40+O41 -> 0.1
B43: G | C43: ETHICS AND VALUES | K43: 0.1 | M43: TARGET | N43: ACTUAL | O43: COMPUTED
...

Sheet ScoreBoard
B1: # | C1: Laboratory Activities | D1: =E1+G1+I1+K1+#REF! -> #REF! | E1: 20 | F1: 5 | G1: 40 | H1: 5 | I1: 20 | J1: 5 | K1: 20 | L1: 5 | M1: =N1+P1+R1+T1 -> 100 | N1: 25 | O1: 5 | P1: 25 | Q1: 5 | R1: 25 | S1: 5 | T1: 25 | U1: 5 | V1: =W1+Y1+AA1 -> 100 | W1: 30 | X1: 5 | Y1: 40 | Z1: 5 | AA1: 30 | AB1: 5 | AC1: =AD1+AF1 -> 100 | AD1: 50 | AE1: 5 | AF1: 50 | AG1: 5 | AH1: =AI1+AK1 -> 100 | AI1: 80 | AJ1: 5 | AK1: 20 | AL1: 5
D2: Employee Engagement | E2: Team Work and Collaboration | G2: Problem-solving and Understanding the Requirements | I2: Communication Skills | K2: Intiative and Ownership | M2: Productivity | N2: Efficiency and Output Quality | P2: Adherence to deadlines and Workload Management | R2: Knowledge of Tools and Technologies | T2: Task Execution and Application of Knowledge | V2: Work Quality | W2: Attention to Detail | Y2: Quality of Work | AA2: Work Output | AC2: Customer Satisfaction/Service Level Commitments | AD2: Meets deadline for assignments and coourse requirements | AF2: Actively engage with teammates during recitations or offering assistance and feedback | AH2: Self-improvement | AI2: Summative Assessment | AK2: Grooming and Attire + Weekly Report | AN2: # | AO2: Assessments | AP2: Rating | AQ2: Score | AR2: Equivalent | AS2: Total Items | AU2: # | AV2: Weekly Report | AW2: Status
D3: =IFERROR( SUM(E3, G3, I3, K3) / (COUNTIF(E3, "<>0") + COUNTIF(G3, "<>0") + COUNTIF(I3, "<>0") + COUNTIF(K3, "<>0")), 0) -> 4.71875 | E3: =IFERROR(SUMIF(OFFSET(F4, 0, 0, COUNTA(F:F)-3, 1), "<>0") / COUNTIF(OFFSET(F4, 0, 0, COUNTA(F:F)-3, 1), "<>0"), 0) -> 5 | G3: =IFERROR(SUMIF(OFFSET(H4, 0, 0, COUNTA(H:H)-3, 1), "<>0") / COUNTIF(OFFSET(H4, 0, 0, COUNTA(H:H)-3, 1), "<>0"), 0) -> 4.375 | I3: =IFERROR(SUMIF(OFFSET(J4, 0, 0, COUNTA(J:J)-3, 1), "<>0") / COUNTIF(OFFSET(J4, 0, 0, COUNTA(J:J)-3, 1), "<>0"), 0) -> 4.5 | K3: =IFERROR(SUMIF(OFFSET(L4, 0, 0, COUNTA(L:L)-3, 1), "<>0") / COUNTIF(OFFSET(L4, 0, 0, COUNTA(L:L)-3, 1), "<>0"), 0) -> 5 | M3: =IFERROR(SUM(N3, P3, R3, T3) / (COUNTIF(N3, "<>0") + COUNTIF(P3, "<>0") + COUNTIF(R3, "<>0") + COUNTIF(T3, "<>0")), 0) -> 0 | N3: =IFERROR(SUMIF(OFFSET(O4, 0, 0, COUNTA(O:O)-3, 1), "<>0") / COUNTIF(OFFSET(O4, 0, 0, COUNTA(O:O)-3, 1), "<>0"), 0) -> 0 | P3: =IFERROR(SUMIF(OFFSET(Q4, 0, 0, COUNTA(Q:Q)-3, 1), "<>0") / COUNTIF(OFFSET(Q4, 0, 0, COUNTA(Q:Q)-3, 1), "<>0"), 0) -> 0 | R3: =IFERROR(SUMIF(OFFSET(S4, 0, 0, COUNTA(S:S)-3, 1), "<>0") / COUNTIF(OFFSET(S4, 0, 0, COUNTA(S:S)-3, 1), "<>0"), 0) -> 0 | T3: =IFERROR(SUMIF(OFFSET(U4, 0, 0, COUNTA(U:U)-3, 1), "<>0") / COUNTIF(OFFSET(U4, 0, 0, COUNTA(U:U)-3, 1), "<>0"), 0) -> 0 | V3: =IFERROR(SUM(W3, Y3, AA3) / (COUNTIF(W3, "<>0") + COUNTIF(Y3, "<>0") + COUNTIF(AA3, "<>0")), 0) -> 0 | W3: =IFERROR(SUMIF(OFFSET(X4, 0, 0, COUNTA(X:X)-3, 1), "<>0") / COUNTIF(OFFSET(X4, 0, 0, COUNTA(X:X)-3, 1), "<>0"), 0) -> 0 | Y3: =IFERROR(SUMIF(OFFSET(Z4, 0, 0, COUNTA(Z:Z)-3, 1), "<>0") / COUNTIF(OFFSET(Z4, 0, 0, COUNTA(Z:Z)-3, 1), "<>0"), 0) -> 0 | AA3: =IFERROR(SUMIF(OFFSET(AB4, 0, 0, COUNTA(AB:AB)-3, 1), "<>0") / COUNTIF(OFFSET(AB4, 0, 0, COUNTA(AB:AB)-3, 1), "<>0"), 0) -> 0 | AC3: =IFERROR(SUM(AD3, AF3) / (COUNTIF(AD3, "<>0") + COUNTIF(AF3, "<>0")), 0) -> 0 | AD3: =IFERROR(SUMIF(OFFSET(AE4, 0, 0, COUNTA(AE:AE)-3, 1), "<>0") / COUNTIF(OFFSET(AE4, 0, 0, COUNTA(AE:AE)-3, 1), "<>0"), 0) -> 0 | AF3: =IFERROR(SUMIF(OFFSET(AG4, 0, 0, COUNTA(AG:AG)-3, 1), "<>0") / COUNTIF(OFFSET(AG4, 0, 0, COUNTA(AG:AG)-3, 1), "<>0"), 0) -> 0 | AH3: =IFERROR(SUM(AI3, AK3) / (COUNTIF(AI3, "<>0") + COUNTIF(AK3, "<>0")), 0) -> 2.5 | AI3: =IFERROR(SUMIF(OFFSET(AJ4, 0, 0, COUNTA(AJ:AJ)-3, 1), "<>0") / COUNTIF(OFFSET(AJ4, 0, 0, COUNTA(AJ:AJ)-3, 1), "<>0"), 0) -> 2.5 | AK3: =IFERROR(SUMIF(OFFSET(AL4, 0, 0, COUNTA(AL:AL)-3, 1), "<>0") / COUNTIF(OFFSET(AL4, 0, 0, COUNTA(AL:AL)-3, 1), "<>0"), 0) -> 0 | AR3: =IFERROR(SUMIF(OFFSET(AR4, 0, 0, COUNTA(AR4:AR1000), 1), "<>0") / COUNTIF(OFFSET(AR4, 0, 0, COUNTA(AR4:AR1000), 1), "<>0"), 0) -> 50
C4: Portfolio | D4: =+E4+G4+I4+K4 -> 93 | E4: 20 | F4: =E4*$F$1/$E$1 -> 5 | G4: 35 | H4: =G4*$H$1/$G$1 -> 4.375 | I4: 18 | J4: =I4*$J$1/$I$1 -> 4.5 | K4: 20 | L4: =K4*$L$1/$K$1 -> 5 | M4: =N4+P4+R4+T4 -> 0 | O4: =N4*$O$1/$N$1 -> 0 | Q4: =P4*$Q$1/$P$1 -> 0 | S4: =R4*$S$1/$R$1 -> 0 | U4: =T4*$U$1/$T$1 -> 0 | V4: =+W4+Y4+AA4 -> 0 | X4: =W4*$X$1/$W$1 -> 0 | Z4: =Y4*$Z$1/$Y$1 -> 0 | AB4: =AA4*$AB$1/$AA$1 -> 0 | AC4: =+AD4+AF4 -> 0 | AE4: =AD4*$AE$1/$AD$1 -> 0 | AG4: =AF4*$AG$1/$AF$1 -> 0 | AH4: =+AI4+AK4 -> 40 | AI4: =AR4*0.8 -> 40 | AJ4: =AI4*$AJ$1/$AI$1 -> 2.5 | AL4: =AK4*$AL$1/$AK$1 -> 0 | AN4: 1 | AO4: Git and Version Control | AP4: =IF(ISNUMBER(AR4), IF(AR4<=60, 1, IF(AR4<=70, 2, IF(AR4<=85, 3, IF(AR4<=96, 4, 5)))), 0) -> 1 | AR4: =IFERROR((AQ4/AS4)*50+50, " ") -> 50 | AS4: 100 | AU4: 1 | AV4: Week 01 | AW4: TRUE
C5: QTab Modules | D5: =+E5+G5+I5+K5 -> 0 | F5: =E5*$F$1/$E$1 -> 0 | H5: =G5*$H$1/$G$1 -> 0 | J5: =I5*$J$1/$I$1 -> 0 | L5: =K5*$L$1/$K$1 -> 0 | M5: =N5+P5+R5+T5 -> 0 | O5: =N5*$O$1/$N$1 -> 0 | Q5: =P5*$Q$1/$P$1 -> 0 | S5: =R5*$S$1/$R$1 -> 0 | U5: =T5*$U$1/$T$1 -> 0 | V5: =+W5+Y5+AA5 -> 0 | X5: =W5*$X$1/$W$1 -> 0 | Z5: =Y5*$Z$1/$Y$1 -> 0 | AB5: =AA5*$AB$1/$AA$1 -> 0 | AC5: =+AD5+AF5 -> 0 | AE5: =AD5*$AE$1/$AD$1 -> 0 | AG5: =AF5*$AG$1/$AF$1 -> 0 | AH5: =+AI5+AK5 -> 40 | AI5: =AR5*0.8 -> 40 | AJ5: =AI5*$AJ$1/$AI$1 -> 2.5 | AL5: =AK5*$AL$1/$AK$1 -> 0 | AN5: 2 | AO5: JavaScript | AP5: =IF(ISNUMBER(AR5), IF(AR5<=60, 1, IF(AR5<=70, 2, IF(AR5<=85, 3, IF(AR5<=96, 4, 5)))), 0) -> 1 | AR5: =IFERROR((AQ5/AS5)*50+50, " ") -> 50 | AS5: 50 | AU5: 2 | AV5: Week 02 | AW5: TRUE
C6: Pokemon | D6: =+E6+G6+I6+K6 -> 0 | F6: =E6*$F$1/$E$1 -> 0 | H6: =G6*$H$1/$G$1 -> 0 | J6: =I6*$J$1/$I$1 -> 0 | L6: =K6*$L$1/$K$1 -> 0 | M6: =N6+P6+R6+T6 -> 0 | O6: =N6*$O$1/$N$1 -> 0 | Q6: =P6*$Q$1/$P$1 -> 0 | S6: =R6*$S$1/$R$1 -> 0 | U6: =T6*$U$1/$T$1 -> 0 | V6: =+W6+Y6+AA6 -> 0 | X6: =W6*$X$1/$W$1 -> 0 | Z6: =Y6*$Z$1/$Y$1 -> 0 | AB6: =AA6*$AB$1/$AA$1 -> 0 | AC6: =+AD6+AF6 -> 0 | AE6: =AD6*$AE$1/$AD$1 -> 0 | AG6: =AF6*$AG$1/$AF$1 -> 0 | AH6: =+AI6+AK6 -> 40 | AI6: =AR6*0.8 -> 40 | AJ6: =AI6*$AJ$1/$AI$1 -> 2.5 | AL6: =AK6*$AL$1/$AK$1 -> 0 | AN6: 2 | AO6: Data Modeling/DBMS | AP6: =IF(ISNUMBER(AR6), IF(AR6<=60, 1, IF(AR6<=70, 2, IF(AR6<=85, 3, IF(AR6<=96, 4, 5)))), 0) -> 1 | AR6: =IFERROR((AQ6/AS6)*50+50, " ") -> 50 | AS6: 30 | AU6: 3 | AV6: Week 03 | AW6: TRUE
F7: =E7*$F$1/$E$1 -> 0 | H7: =G7*$H$1/$G$1 -> 0 | J7: =I7*$J$1/$I$1 -> 0 | L7: =K7*$L$1/$K$1 -> 0 | O7: =N7*$O$1/$N$1 -> 0 | Q7: =P7*$Q$1/$P$1 -> 0 | S7: =R7*$S$1/$R$1 -> 0 | U7: =T7*$U$1/$T$1 -> 0 | X7: =W7*$X$1/$W$1 -> 0 | Z7: =Y7*$Z$1/$Y$1 -> 0 | AB7: =AA7*$AB$1/$AA$1 -> 0 | AE7: =AD7*$AE$1/$AD$1 -> 0 | AG7: =AF7*$AG$1/$AF$1 -> 0 | AH7: =+AI7+AK7 -> 40 | AI7: =AR7*0.8 -> 40 | AJ7: =AI7*$AJ$1/$AI$1 -> 2.5 | AL7: =AK7*$AL$1/$AK$1 -> 0 | AN7: 2 | AO7: MERN | AP7: =IF(ISNUMBER(AR7), IF(AR7<=60, 1, IF(AR7<=70, 2, IF(AR7<=85, 3, IF(AR7<=96, 4, 5)))), 0) -> 1 | AR7: =IFERROR((AQ7/AS7)*50+50, " ") -> 50 | AS7: 80 | AU7: 4 | AV7: Week 04 | AW7: TRUE
F8: =E8*$F$1/$E$1 -> 0 | H8: =G8*$H$1/$G$1 -> 0 | J8: =I8*$J$1/$I$1 -> 0 | L8: =K8*$L$1/$K$1 -> 0 | O8: =N8*$O$1/$N$1 -> 0 | Q8: =P8*$Q$1/$P$1 -> 0 | S8: =R8*$S$1/$R$1 -> 0 | U8: =T8*$U$1/$T$1 -> 0 | X8: =W8*$X$1/$W$1 -> 0 | Z8: =Y8*$Z$1/$Y$1 -> 0 | AB8: =AA8*$AB$1/$AA$1 -> 0 | AE8: =AD8*$AE$1/$AD$1 -> 0 | AG8: =AF8*$AG$1/$AF$1 -> 0 | AH8: =+AI8+AK8 -> 40 | AI8: =AR8*0.8 -> 40 | AJ8: =AI8*$AJ$1/$AI$1 -> 2.5 | AL8: =AK8*$AL$1/$AK$1 -> 0 | AN8: 2 | AO8: SDLC | AP8: =IF(ISNUMBER(AR8), IF(AR8<=60, 1, IF(AR8<=70, 2, IF(AR8<=85, 3, IF(AR8<=96, 4, 5)))), 0) -> 1 | AR8: =IFERROR((AQ8/AS8)*50+50, " ") -> 50 | AS8: 50 | AU8: 5 | AV8: Week 05 | AW8: FALSE
F9: =E9*$F$1/$E$1 -> 0 | H9: =G9*$H$1/$G$1 -> 0 | J9: =I9*$J$1/$I$1 -> 0 | L9: =K9*$L$1/$K$1 -> 0 | O9: =N9*$O$1/$N$1 -> 0 | Q9: =P9*$Q$1/$P$1 -> 0 | S9: =R9*$S$1/$R$1 -> 0 | U9: =T9*$U$1/$T$1 -> 0 | X9: =W9*$X$1/$W$1 -> 0 | Z9: =Y9*$Z$1/$Y$1 -> 0 | AB9: =AA9*$AB$1/$AA$1 -> 0 | AE9: =AD9*$AE$1/$AD$1 -> 0 | AG9: =AF9*$AG$1/$AF$1 -> 0 | AH9: =+AI9+AK9 -> 40 | AI9: =AR9*0.8 -> 40 | AJ9: =AI9*$AJ$1/$AI$1 -> 2.5 | AL9: =AK9*$AL$1/$AK$1 -> 0 | AN9: 2 | AO9: Defect Reports | AP9: =IF(ISNUMBER(AR9), IF(AR9<=60, 1, IF(AR9<=70, 2, IF(AR9<=85, 3, IF(AR9<=96, 4, 5)))), 0) -> 1 | AR9: =IFERROR((AQ9/AS9)*50+50, " ") -> 50 | AS9: 50 | AU9: 6 | AV9: Week 06 | AW9: FALSE
F10: =E10*$F$1/$E$1 -> 0 | H10: =G10*$H$1/$G$1 -> 0 | J10: =I10*$J$1/$I$1 -> 0 | L10: =K10*$L$1/$K$1 -> 0 | O10: =N10*$O$1/$N$1 -> 0 | Q10: =P10*$Q$1/$P$1 -> 0 | S10: =R10*$S$1/$R$1 -> 0 | U10: =T10*$U$1/$T$1 -> 0 | X10: =W10*$X$1/$W$1 -> 0 | Z10: =Y10*$Z$1/$Y$1 -> 0 | AB10: =AA10*$AB$1/$AA$1 -> 0 | AE10: =AD10*$AE$1/$AD$1 -> 0 | AG10: =AF10*$AG$1/$AF$1 -> 0 | AH10: =+AI10+AK10 -> 40 | AI10: =AR10*0.8 -> 40 | AJ10: =AI10*$AJ$1/$AI$1 -> 2.5 | AL10: =AK10*$AL$1/$AK$1 -> 0 | AN10: 2 | AO10: SQL/Data validation | AP10: =IF(ISNUMBER(AR10), IF(AR10<=60, 1, IF(AR10<=70, 2, IF(AR10<=85, 3, IF(AR10<=96, 4, 5)))), 0) -> 1 | AR10: =IFERROR((AQ10/AS10)*50+50, " ") -> 50 | AS10: 30 | AU10: 7 | AV10: Week 07 | AW10: FALSE
F11: =E11*$F$1/$E$1 -> 0 | H11: =G11*$H$1/$G$1 -> 0 | J11: =I11*$J$1/$I$1 -> 0 | L11: =K11*$L$1/$K$1 -> 0 | O11: =N11*$O$1/$N$1 -> 0 | Q11: =P11*$Q$1/$P$1 -> 0 | S11: =R11*$S$1/$R$1 -> 0 | U11: =T11*$U$1/$T$1 -> 0 | X11: =W11*$X$1/$W$1 -> 0 | Z11: =Y11*$Z$1/$Y$1 -> 0 | AB11: =AA11*$AB$1/$AA$1 -> 0 | AE11: =AD11*$AE$1/$AD$1 -> 0 | AG11: =AF11*$AG$1/$AF$1 -> 0 | AH11: =+AI11+AK11 -> 40 | AI11: =AR11*0.8 -> 40 | AJ11: =AI11*$AJ$1/$AI$1 -> 2.5 | AL11: =AK11*$AL$1/$AK$1 -> 0 | AN11: 2 | AO11: Automation | AP11: =IF(ISNUMBER(AR11), IF(AR11<=60, 1, IF(AR11<=70, 2, IF(AR11<=85, 3, IF(AR11<=96, 4, 5)))), 0) -> 1 | AR11: =IFERROR((AQ11/AS11)*50+50, " ") -> 50 | AS11: 50 | AU11: 8 | AV11: Week 08 | AW11: FALSE
F12: =E12*$F$1/$E$1 -> 0 | H12: =G12*$H$1/$G$1 -> 0 | J12: =I12*$J$1/$I$1 -> 0 | L12: =K12*$L$1/$K$1 -> 0 | O12: =N12*$O$1/$N$1 -> 0 | Q12: =P12*$Q$1/$P$1 -> 0 | S12: =R12*$S$1/$R$1 -> 0 | U12: =T12*$U$1/$T$1 -> 0 | X12: =W12*$X$1/$W$1 -> 0 | Z12: =Y12*$Z$1/$Y$1 -> 0 | AB12: =AA12*$AB$1/$AA$1 -> 0 | AE12: =AD12*$AE$1/$AD$1 -> 0 | AG12: =AF12*$AG$1/$AF$1 -> 0 | AH12: =+AI12+AK12 -> 40 | AI12: =AR12*0.8 -> 40 | AJ12: =AI12*$AJ$1/$AI$1 -> 2.5 | AL12: =AK12*$AL$1/$AK$1 -> 0 | AN12: 2 | AO12: Logic and Foundation | AP12: =IF(ISNUMBER(AR12), IF(AR12<=60, 1, IF(AR12<=70, 2, IF(AR12<=85, 3, IF(AR12<=96, 4, 5)))), 0) -> 1 | AR12: =IFERROR((AQ12/AS12)*50+50, " ") -> 50 | AS12: 50 | AU12: 9 | AV12: Week 09 | AW12: FALSE
F13: =E13*$F$1/$E$1 -> 0 | H13: =G13*$H$1/$G$1 -> 0 | J13: =I13*$J$1/$I$1 -> 0 | L13: =K13*$L$1/$K$1 -> 0 | O13: =N13*$O$1/$N$1 -> 0 | Q13: =P13*$Q$1/$P$1 -> 0 | S13: =R13*$S$1/$R$1 -> 0 | U13: =T13*$U$1/$T$1 -> 0 | X13: =W13*$X$1/$W$1 -> 0 | Z13: =Y13*$Z$1/$Y$1 -> 0 | AB13: =AA13*$AB$1/$AA$1 -> 0 | AE13: =AD13*$AE$1/$AD$1 -> 0 | AG13: =AF13*$AG$1/$AF$1 -> 0 | AH13: =+AI13+AK13 -> 40 | AI13: =AR13*0.8 -> 40 | AJ13: =AI13*$AJ$1/$AI$1 -> 2.5 | AL13: =AK13*$AL$1/$AK$1 -> 0 | AN13: 2 | AO13: OOP | AP13: =IF(ISNUMBER(AR13), IF(AR13<=60, 1, IF(AR13<=70, 2, IF(AR13<=85, 3, IF(AR13<=96, 4, 5)))), 0) -> 1 | AR13: =IFERROR((AQ13/AS13)*50+50, " ") -> 50 | AS13: 50 | AU13: 10 | AV13: Week 10 | AW13: FALSE
F14: =E14*$F$1/$E$1 -> 0 | H14: =G14*$H$1/$G$1 -> 0 | J14: =I14*$J$1/$I$1 -> 0 | L14: =K14*$L$1/$K$1 -> 0 | O14: =N14*$O$1/$N$1 -> 0 | Q14: =P14*$Q$1/$P$1 -> 0 | S14: =R14*$S$1/$R$1 -> 0 | U14: =T14*$U$1/$T$1 -> 0 | X14: =W14*$X$1/$W$1 -> 0 | Z14: =Y14*$Z$1/$Y$1 -> 0 | AB14: =AA14*$AB$1/$AA$1 -> 0 | AE14: =AD14*$AE$1/$AD$1 -> 0 | AG14: =AF14*$AG$1/$AF$1 -> 0 | AJ14: =AI14*$AJ$1/$AI$1 -> 0 | AL14: =AK14*$AL$1/$AK$1 -> 0 | AU14: 11 | AV14: Week 11 | AW14: FALSE
F15: =E15*$F$1/$E$1 -> 0 | H15: =G15*$H$1/$G$1 -> 0 | J15: =I15*$J$1/$I$1 -> 0 | L15: =K15*$L$1/$K$1 -> 0 | O15: =N15*$O$1/$N$1 -> 0 | Q15: =P15*$Q$1/$P$1 -> 0 | S15: =R15*$S$1/$R$1 -> 0 | U15: =T15*$U$1/$T$1 -> 0 | X15: =W15*$X$1/$W$1 -> 0 | Z15: =Y15*$Z$1/$Y$1 -> 0 | AB15: =AA15*$AB$1/$AA$1 -> 0 | AE15: =AD15*$AE$1/$AD$1 -> 0 | AG15: =AF15*$AG$1/$AF$1 -> 0 | AJ15: =AI15*$AJ$1/$AI$1 -> 0 | AL15: =AK15*$AL$1/$AK$1 -> 0 | AU15: 12 | AV15: Week 12 | AW15: FALSE
F16: =E16*$F$1/$E$1 -> 0 | H16: =G16*$H$1/$G$1 -> 0 | J16: =I16*$J$1/$I$1 -> 0 | L16: =K16*$L$1/$K$1 -> 0 | O16: =N16*$O$1/$N$1 -> 0 | Q16: =P16*$Q$1/$P$1 -> 0 | S16: =R16*$S$1/$R$1 -> 0 | U16: =T16*$U$1/$T$1 -> 0 | X16: =W16*$X$1/$W$1 -> 0 | Z16: =Y16*$Z$1/$Y$1 -> 0 | AB16: =AA16*$AB$1/$AA$1 -> 0 | AE16: =AD16*$AE$1/$AD$1 -> 0 | AG16: =AF16*$AG$1/$AF$1 -> 0 | AJ16: =AI16*$AJ$1/$AI$1 -> 0 | AL16: =AK16*$AL$1/$AK$1 -> 0 | AU16: 13 | AV16: Week 13 | AW16: FALSE
F17: =E17*$F$1/$E$1 -> 0 | H17: =G17*$H$1/$G$1 -> 0 | J17: =I17*$J$1/$I$1 -> 0 | L17: =K17*$L$1/$K$1 -> 0 | O17: =N17*$O$1/$N$1 -> 0 | Q17: =P17*$Q$1/$P$1 -> 0 | S17: =R17*$S$1/$R$1 -> 0 | U17: =T17*$U$1/$T$1 -> 0 | X17: =W17*$X$1/$W$1 -> 0 | Z17: =Y17*$Z$1/$Y$1 -> 0 | AB17: =AA17*$AB$1/$AA$1 -> 0 | AE17: =AD17*$AE$1/$AD$1 -> 0 | AG17: =AF17*$AG$1/$AF$1 -> 0 | AJ17: =AI17*$AJ$1/$AI$1 -> 0 | AL17: =AK17*$AL$1/$AK$1 -> 0 | AU17: 14 | AV17: Week 14 | AW17: FALSE
F18: =E18*$F$1/$E$1 -> 0 | H18: =G18*$H$1/$G$1 -> 0 | J18: =I18*$J$1/$I$1 -> 0 | L18: =K18*$L$1/$K$1 -> 0 | O18: =N18*$O$1/$N$1 -> 0 | Q18: =P18*$Q$1/$P$1 -> 0 | S18: =R18*$S$1/$R$1 -> 0 | U18: =T18*$U$1/$T$1 -> 0 | X18: =W18*$X$1/$W$1 -> 0 | Z18: =Y18*$Z$1/$Y$1 -> 0 | AB18: =AA18*$AB$1/$AA$1 -> 0 | AE18: =AD18*$AE$1/$AD$1 -> 0 | AG18: =AF18*$AG$1/$AF$1 -> 0 | AJ18: =AI18*$AJ$1/$AI$1 -> 0 | AL18: =AK18*$AL$1/$AK$1 -> 0 | AU18: 15 | AV18: Week 15 | AW18: FALSE
F19: =E19*$F$1/$E$1 -> 0 | H19: =G19*$H$1/$G$1 -> 0 | J19: =I19*$J$1/$I$1 -> 0 | L19: =K19*$L$1/$K$1 -> 0 | O19: =N19*$O$1/$N$1 -> 0 | Q19: =P19*$Q$1/$P$1 -> 0 | S19: =R19*$S$1/$R$1 -> 0 | U19: =T19*$U$1/$T$1 -> 0 | X19: =W19*$X$1/$W$1 -> 0 | Z19: =Y19*$Z$1/$Y$1 -> 0 | AB19: =AA19*$AB$1/$AA$1 -> 0 | AE19: =AD19*$AE$1/$AD$1 -> 0 | AG19: =AF19*$AG$1/$AF$1 -> 0 | AJ19: =AI19*$AJ$1/$AI$1 -> 0 | AL19: =AK19*$AL$1/$AK$1 -> 0
F20: =E20*$F$1/$E$1 -> 0 | H20: =G20*$H$1/$G$1 -> 0 | J20: =I20*$J$1/$I$1 -> 0 | L20: =K20*$L$1/$K$1 -> 0 | O20: =N20*$O$1/$N$1 -> 0 | Q20: =P20*$Q$1/$P$1 -> 0 | S20: =R20*$S$1/$R$1 -> 0 | U20: =T20*$U$1/$T$1 -> 0 | X20: =W20*$X$1/$W$1 -> 0 | Z20: =Y20*$Z$1/$Y$1 -> 0 | AB20: =AA20*$AB$1/$AA$1 -> 0 | AE20: =AD20*$AE$1/$AD$1 -> 0 | AG20: =AF20*$AG$1/$AF$1 -> 0 | AJ20: =AI20*$AJ$1/$AI$1 -> 0 | AL20: =AK20*$AL$1/$AK$1 -> 0
F21: =E21*$F$1/$E$1 -> 0 | H21: =G21*$H$1/$G$1 -> 0 | J21: =I21*$J$1/$I$1 -> 0 | L21: =K21*$L$1/$K$1 -> 0 | O21: =N21*$O$1/$N$1 -> 0 | Q21: =P21*$Q$1/$P$1 -> 0 | S21: =R21*$S$1/$R$1 -> 0 | U21: =T21*$U$1/$T$1 -> 0 | X21: =W21*$X$1/$W$1 -> 0 | Z21: =Y21*$Z$1/$Y$1 -> 0 | AB21: =AA21*$AB$1/$AA$1 -> 0 | AE21: =AD21*$AE$1/$AD$1 -> 0 | AG21: =AF21*$AG$1/$AF$1 -> 0 | AJ21: =AI21*$AJ$1/$AI$1 -> 0 | AL21: =AK21*$AL$1/$AK$1 -> 0
F22: =E22*$F$1/$E$1 -> 0 | H22: =G22*$H$1/$G$1 -> 0 | J22: =I22*$J$1/$I$1 -> 0 | L22: =K22*$L$1/$K$1 -> 0 | O22: =N22*$O$1/$N$1 -> 0 | Q22: =P22*$Q$1/$P$1 -> 0 | S22: =R22*$S$1/$R$1 -> 0 | U22: =T22*$U$1/$T$1 -> 0 | X22: =W22*$X$1/$W$1 -> 0 | Z22: =Y22*$Z$1/$Y$1 -> 0 | AB22: =AA22*$AB$1/$AA$1 -> 0 | AE22: =AD22*$AE$1/$AD$1 -> 0 | AG22: =AF22*$AG$1/$AF$1 -> 0 | AJ22: =AI22*$AJ$1/$AI$1 -> 0 | AL22: =AK22*$AL$1/$AK$1 -> 0
F23: =E23*$F$1/$E$1 -> 0 | H23: =G23*$H$1/$G$1 -> 0 | J23: =I23*$J$1/$I$1 -> 0 | L23: =K23*$L$1/$K$1 -> 0 | O23: =N23*$O$1/$N$1 -> 0 | Q23: =P23*$Q$1/$P$1 -> 0 | S23: =R23*$S$1/$R$1 -> 0 | U23: =T23*$U$1/$T$1 -> 0 | X23: =W23*$X$1/$W$1 -> 0 | Z23: =Y23*$Z$1/$Y$1 -> 0 | AB23: =AA23*$AB$1/$AA$1 -> 0 | AE23: =AD23*$AE$1/$AD$1 -> 0 | AG23: =AF23*$AG$1/$AF$1 -> 0 | AJ23: =AI23*$AJ$1/$AI$1 -> 0 | AL23: =AK23*$AL$1/$AK$1 -> 0
F24: =E24*$F$1/$E$1 -> 0 | H24: =G24*$H$1/$G$1 -> 0 | J24: =I24*$J$1/$I$1 -> 0 | L24: =K24*$L$1/$K$1 -> 0 | O24: =N24*$O$1/$N$1 -> 0 | Q24: =P24*$Q$1/$P$1 -> 0 | S24: =R24*$S$1/$R$1 -> 0 | U24: =T24*$U$1/$T$1 -> 0 | X24: =W24*$X$1/$W$1 -> 0 | Z24: =Y24*$Z$1/$Y$1 -> 0 | AB24: =AA24*$AB$1/$AA$1 -> 0 | AE24: =AD24*$AE$1/$AD$1 -> 0 | AG24: =AF24*$AG$1/$AF$1 -> 0 | AJ24: =AI24*$AJ$1/$AI$1 -> 0 | AL24: =AK24*$AL$1/$AK$1 -> 0
F25: =E25*$F$1/$E$1 -> 0 | H25: =G25*$H$1/$G$1 -> 0 | J25: =I25*$J$1/$I$1 -> 0 | L25: =K25*$L$1/$K$1 -> 0 | O25: =N25*$O$1/$N$1 -> 0 | Q25: =P25*$Q$1/$P$1 -> 0 | S25: =R25*$S$1/$R$1 -> 0 | U25: =T25*$U$1/$T$1 -> 0 | X25: =W25*$X$1/$W$1 -> 0 | Z25: =Y25*$Z$1/$Y$1 -> 0 | AB25: =AA25*$AB$1/$AA$1 -> 0 | AE25: =AD25*$AE$1/$AD$1 -> 0 | AG25: =AF25*$AG$1/$AF$1 -> 0 | AJ25: =AI25*$AJ$1/$AI$1 -> 0 | AL25: =AK25*$AL$1/$AK$1 -> 0
F26: =E26*$F$1/$E$1 -> 0 | H26: =G26*$H$1/$G$1 -> 0 | J26: =I26*$J$1/$I$1 -> 0 | L26: =K26*$L$1/$K$1 -> 0 | O26: =N26*$O$1/$N$1 -> 0 | Q26: =P26*$Q$1/$P$1 -> 0 | S26: =R26*$S$1/$R$1 -> 0 | U26: =T26*$U$1/$T$1 -> 0 | X26: =W26*$X$1/$W$1 -> 0 | Z26: =Y26*$Z$1/$Y$1 -> 0 | AB26: =AA26*$AB$1/$AA$1 -> 0 | AE26: =AD26*$AE$1/$AD$1 -> 0 | AG26: =AF26*$AG$1/$AF$1 -> 0 | AJ26: =AI26*$AJ$1/$AI$1 -> 0 | AL26: =AK26*$AL$1/$AK$1 -> 0
F27: =E27*$F$1/$E$1 -> 0 | H27: =G27*$H$1/$G$1 -> 0 | J27: =I27*$J$1/$I$1 -> 0 | L27: =K27*$L$1/$K$1 -> 0 | O27: =N27*$O$1/$N$1 -> 0 | Q27: =P27*$Q$1/$P$1 -> 0 | S27: =R27*$S$1/$R$1 -> 0 | U27: =T27*$U$1/$T$1 -> 0 | X27: =W27*$X$1/$W$1 -> 0 | Z27: =Y27*$Z$1/$Y$1 -> 0 | AB27: =AA27*$AB$1/$AA$1 -> 0 | AE27: =AD27*$AE$1/$AD$1 -> 0 | AG27: =AF27*$AG$1/$AF$1 -> 0 | AJ27: =AI27*$AJ$1/$AI$1 -> 0 | AL27: =AK27*$AL$1/$AK$1 -> 0
F28: =E28*$F$1/$E$1 -> 0 | H28: =G28*$H$1/$G$1 -> 0 | J28: =I28*$J$1/$I$1 -> 0 | L28: =K28*$L$1/$K$1 -> 0 | O28: =N28*$O$1/$N$1 -> 0 | Q28: =P28*$Q$1/$P$1 -> 0 | S28: =R28*$S$1/$R$1 -> 0 | U28: =T28*$U$1/$T$1 -> 0 | X28: =W28*$X$1/$W$1 -> 0 | Z28: =Y28*$Z$1/$Y$1 -> 0 | AB28: =AA28*$AB$1/$AA$1 -> 0 | AE28: =AD28*$AE$1/$AD$1 -> 0 | AG28: =AF28*$AG$1/$AF$1 -> 0 | AJ28: =AI28*$AJ$1/$AI$1 -> 0 | AL28: =AK28*$AL$1/$AK$1 -> 0
F29: =E29*$F$1/$E$1 -> 0 | H29: =G29*$H$1/$G$1 -> 0 | J29: =I29*$J$1/$I$1 -> 0 | L29: =K29*$L$1/$K$1 -> 0 | O29: =N29*$O$1/$N$1 -> 0 | Q29: =P29*$Q$1/$P$1 -> 0 | S29: =R29*$S$1/$R$1 -> 0 | U29: =T29*$U$1/$T$1 -> 0 | X29: =W29*$X$1/$W$1 -> 0 | Z29: =Y29*$Z$1/$Y$1 -> 0 | AB29: =AA29*$AB$1/$AA$1 -> 0 | AE29: =AD29*$AE$1/$AD$1 -> 0 | AG29: =AF29*$AG$1/$AF$1 -> 0 | AJ29: =AI29*$AJ$1/$AI$1 -> 0 | AL29: =AK29*$AL$1/$AK$1 -> 0
F30: =E30*$F$1/$E$1 -> 0 | H30: =G30*$H$1/$G$1 -> 0 | J30: =I30*$J$1/$I$1 -> 0 | L30: =K30*$L$1/$K$1 -> 0 | O30: =N30*$O$1/$N$1 -> 0 | Q30: =P30*$Q$1/$P$1 -> 0 | S30: =R30*$S$1/$R$1 -> 0 | U30: =T30*$U$1/$T$1 -> 0 | X30: =W30*$X$1/$W$1 -> 0 | Z30: =Y30*$Z$1/$Y$1 -> 0 | AB30: =AA30*$AB$1/$AA$1 -> 0 | AE30: =AD30*$AE$1/$AD$1 -> 0 | AG30: =AF30*$AG$1/$AF$1 -> 0 | AJ30: =AI30*$AJ$1/$AI$1 -> 0 | AL30: =AK30*$AL$1/$AK$1 -> 0
... F39: =E39*$F$1/$E$1 -> 0 | H39: =G39*$H$1/$G$1 -> 0 | J39: =I39*$J$1/$I$1 -> 0 | L39: =K39*$L$1/$K$1 -> 0 | O39: =N39*$O$1/$N$1 -> 0 | Q39: =P39*$Q$1/$P$1 -> 0 | S39: =R39*$S$1/$R$1 -> 0 | U39: =T39*$U$1/$T$1 -> 0 | X39: =W39*$X$1/$W$1 -> 0 | Z39: =Y39*$Z$1/$Y$1 -> 0 | AB39: =AA39*$AB$1/$AA$1 -> 0 | AE39: =AD39*$AE$1/$AD$1 -> 0 | AG39: =AF39*$AG$1/$AF$1 -> 0 | AJ39: =AI39*$AJ$1/$AI$1 -> 0 | AL39: =AK39*$AL$1/$AK$1 -> 0
F40: =E40*$F$1/$E$1 -> 0 | H40: =G40*$H$1/$G$1 -> 0 | J40: =I40*$J$1/$I$1 -> 0 | L40: =K40*$L$1/$K$1 -> 0 | O40: =N40*$O$1/$N$1 -> 0 | Q40: =P40*$Q$1/$P$1 -> 0 | S40: =R40*$S$1/$R$1 -> 0 | U40: =T40*$U$1/$T$1 -> 0 | X40: =W40*$X$1/$W$1 -> 0 | Z40: =Y40*$Z$1/$Y$1 -> 0 | AB40: =AA40*$AB$1/$AA$1 -> 0 | AE40: =AD40*$X$1/$W$1 -> 0 | AG40: =AF40*$AG$1/$AF$1 -> 0 | AJ40: =AI40*$AJ$1/$AI$1 -> 0 | AL40: =AK40*$AL$1/$AK$1 -> 0
F41: =E41*$F$1/$E$1 -> 0 | H41: =G41*$H$1/$G$1 -> 0 | J41: =I41*$J$1/$I$1 -> 0 | L41: =K41*$L$1/$K$1 -> 0 | O41: =N41*$O$1/$N$1 -> 0 | Q41: =P41*$Q$1/$P$1 -> 0 | S41: =R41*$S$1/$R$1 -> 0 | U41: =T41*$U$1/$T$1 -> 0 | X41: =W41*$X$1/$W$1 -> 0 | Z41: =Y41*$Z$1/$Y$1 -> 0 | AB41: =AA41*$AB$1/$AA$1 -> 0 | AE41: =AD41*$X$1/$W$1 -> 0 | AG41: =AF41*$AG$1/$AF$1 -> 0 | AJ41: =AI41*$AJ$1/$AI$1 -> 0 | AL41: =AK41*$AL$1/$AK$1 -> 0
F42: =E42*$F$1/$E$1 -> 0 | H42: =G42*$H$1/$G$1 -> 0 | J42: =I42*$J$1/$I$1 -> 0 | L42: =K42*$L$1/$K$1 -> 0 | O42: =N42*$O$1/$N$1 -> 0 | Q42: =P42*$Q$1/$P$1 -> 0 | S42: =R42*$S$1/$R$1 -> 0 | U42: =T42*$U$1/$T$1 -> 0 | X42: =W42*$X$1/$W$1 -> 0 | Z42: =Y42*$Z$1/$Y$1 -> 0 | AB42: =AA42*$AB$1/$AA$1 -> 0 | AE42: =AD42*$X$1/$W$1 -> 0 | AG42: =AF42*$AG$1/$AF$1 -> 0 | AJ42: =AI42*$AJ$1/$AI$1 -> 0 | AL42: =AK42*$AL$1/$AK$1 -> 0
F43: =E43*$F$1/$E$1 -> 0 | H43: =G43*$H$1/$G$1 -> 0 | J43: =I43*$J$1/$I$1 -> 0 | L43: =K43*$L$1/$K$1 -> 0 | O43: =N43*$O$1/$N$1 -> 0 | Q43: =P43*$Q$1/$P$1 -> 0 | S43: =R43*$S$1/$R$1 -> 0 | U43: =T43*$U$1/$T$1 -> 0 | X43: =W43*$X$1/$W$1 -> 0 | Z43: =Y43*$Z$1/$Y$1 -> 0 | AB43: =AA43*$AB$1/$AA$1 -> 0 | AE43: =AD43*$X$1/$W$1 -> 0 | AG43: =AF43*$AG$1/$AF$1 -> 0 | AJ43: =AI43*$AJ$1/$AI$1 -> 0 | AL43: =AK43*$AL$1/$AK$1 -> 0
F44: =E44*$F$1/$E$1 -> 0 | H44: =G44*$H$1/$G$1 -> 0 | J44: =I44*$J$1/$I$1 -> 0 | L44: =K44*$L$1/$K$1 -> 0 | O44: =N44*$O$1/$N$1 -> 0 | Q44: =P44*$Q$1/$P$1 -> 0 | S44: =R44*$S$1/$R$1 -> 0 | U44: =T44*$U$1/$T$1 -> 0 | X44: =W44*$X$1/$W$1 -> 0 | Z44: =Y44*$Z$1/$Y$1 -> 0 | AB44: =AA44*$AB$1/$AA$1 -> 0 | AE44: =AD44*$X$1/$W$1 -> 0 | AG44: =AF44*$AG$1/$AF$1 -> 0 | AJ44: =AI44*$AJ$1/$AI$1 -> 0 | AL44: =AK44*$AL$1/$AK$1 -> 0
F45: =E45*$F$1/$E$1 -> 0 | H45: =G45*$H$1/$G$1 -> 0 | J45: =I45*$J$1/$I$1 -> 0 | L45: =K45*$L$1/$K$1 -> 0 | O45: =N45*$O$1/$N$1 -> 0 | Q45: =P45*$Q$1/$P$1 -> 0 | S45: =R45*$S$1/$R$1 -> 0 | U45: =T45*$U$1/$T$1 -> 0 | X45: =W45*$X$1/$W$1 -> 0 | Z45: =Y45*$Z$1/$Y$1 -> 0 | AB45: =AA45*$AB$1/$AA$1 -> 0 | AE45: =AD45*$X$1/$W$1 -> 0 | AG45: =AF45*$AG$1/$AF$1 -> 0 | AJ45: =AI45*$AJ$1/$AI$1 -> 0 | AL45: =AK45*$AL$1/$AK$1 -> 0
F46: =E46*$F$1/$E$1 -> 0 | H46: =G46*$H$1/$G$1 -> 0 | J46: =I46*$J$1/$I$1 -> 0 | L46: =K46*$L$1/$K$1 -> 0 | O46: =N46*$O$1/$N$1 -> 0 | Q46: =P46*$Q$1/$P$1 -> 0 | S46: =R46*$S$1/$R$1 -> 0 | U46: =T46*$U$1/$T$1 -> 0 | X46: =W46*$X$1/$W$1 -> 0 | Z46: =Y46*$Z$1/$Y$1 -> 0 | AB46: =AA46*$AB$1/$AA$1 -> 0 | AE46: =AD46*$X$1/$W$1 -> 0 | AG46: =AF46*$AG$1/$AF$1 -> 0 | AJ46: =AI46*$AJ$1/$AI$1 -> 0 | AL46: =AK46*$AL$1/$AK$1 -> 0
F47: =E47*$F$1/$E$1 -> 0 | H47: =G47*$H$1/$G$1 -> 0 | J47: =I47*$J$1/$I$1 -> 0 | L47: =K47*$L$1/$K$1 -> 0 | O47: =N47*$O$1/$N$1 -> 0 | Q47: =P47*$Q$1/$P$1 -> 0 | S47: =R47*$S$1/$R$1 -> 0 | U47: =T47*$U$1/$T$1 -> 0 | X47: =W47*$X$1/$W$1 -> 0 | Z47: =Y47*$Z$1/$Y$1 -> 0 | AB47: =AA47*$AB$1/$AA$1 -> 0 | AE47: =AD47*$X$1/$W$1 -> 0 | AG47: =AF47*$Z$1/$Y$1 -> 0 | AJ47: =AI47*$AJ$1/$AI$1 -> 0 | AL47: =AK47*$AL$1/$AK$1 -> 0
F48: =E48*$F$1/$E$1 -> 0 | H48: =G48*$H$1/$G$1 -> 0 | J48: =I48*$J$1/$I$1 -> 0 | L48: =K48*$L$1/$K$1 -> 0 | O48: =N48*$O$1/$N$1 -> 0 | Q48: =P48*$Q$1/$P$1 -> 0 | S48: =R48*$S$1/$R$1 -> 0 | U48: =T48*$U$1/$T$1 -> 0 | X48: =W48*$X$1/$W$1 -> 0 | Z48: =Y48*$Z$1/$Y$1 -> 0 | AB48: =AA48*$AB$1/$AA$1 -> 0 | AE48: =AD48*$X$1/$W$1 -> 0 | AG48: =AF48*$Z$1/$Y$1 -> 0 | AJ48: =AI48*$AJ$1/$AI$1 -> 0 | AL48: =AK48*$AL$1/$AK$1 -> 0
...

Sheet TrainingRoadmap
B1: SSCGI TRANING ROADMAP
B2: SSCGI TRANING ROADMAP is a comprehesive pragmatic approach design to equip system devloper, business analyst, project manager and quality assurance aspirant with the indemand technical skills, business processes and management strategies. It follows a sequential approach and in phases to cater the diverses roles and specifications required by the client's need.
B5: Each phase comprises structured sections that build on foundational knowledge while progressively introducing advanced tools and techniques.
B7: Training Roadmap Objectives:
B8: 1. Train the participants to design and deliver tailored IT solutions that aling wiht SSCGI's "We Designm You Decide" philosopy to empower customer-centric innovation
B9: 2. Equip participants with technical skills and professional standards to develop reliable, compliant IT solutions
B10: 3. Cultivate teamwork, adaptability and leaderships to produce professionals who contribute to SSCGI's mission and economic development
B11: 4. Prepare the participants with skills and an entrepreneurial mindset to support SSCGI's vision of becoming a global leader in IT solutions.
B14: PHASE 1 TRAINING - ONBOARDING
C15: This phase lays the groundwork by equipping participants with the foundations and core concepts of technical and professional skills essential for MERN full-stack
D20: Trainee Onboarding | H20: HR Orientation and Getting to Know the Company
X25: =216+32+8+8 -> 264
B38: PHASE 2 TRAINING - Upskilling
C40: Business Analyst Deck | M40: SysDev Deck
C41: This deck is tailored for the aspiring business analyst to develop skills for interpreting data, understanding business requirements and designing effective solutions. | M41: This track focuses on equipping trainees with the knowledge and skills required to design, develop, and deploy software systems. It covers foundational programming concepts, full-stack development, software engineering principles, and emerging tools and technologies in system development.
D44: Data Analysis and Visualization | H44: Requirements and Documentation Tools | N44: .NET Full Stack | R44: CI/CD
D47: This 30-hour course introduces the principles, tools and applications of data analysis and visualization. It emphasizes on practicak and hands-on like MS Peoject and PowerBI | H47: This is a 20-hour course module that gain both theoretical and practical skills and managing and documenting requirements using tools and techniques. | N47: This is a 26-hour course module that This module focuses on building end-to-end applications using the .NET ecosystem. Trainees will learn to develop scalable web applications using ASP.NET | R47: This is a 16-hour course module that implement automated development workflows using CI/CD practices.techniques, and monitoring deployed systems using tools like Jenkins, GitHub Actions, and Azure DevOps.
D51: Modeling and Diagramming Skills | H51: Agile and Project Management Tools | N51: PHP | R51: Angular
N54: This is a 24-hour course module that for server-side web development. Participants will gain expertise in developing dynamic websites, working with databases, and using PHP frameworks like Laravel for rapid application development. | R54: This is a 21-hour course module that Angular framework for building dynamic and responsive single-page applications (SPAs). It includes topics on Angular components, services, directives, forms, and state management using RxJS and NgRx.
C59: Project Manager Deck | M59: Quality Assurance
C60: This training equips participants with the tools, techniques, and best practices for effectively planning, executing, and closing projects. It emphasizes team collaboration, risk management, and delivering projects on time and within budget. | M60: This training focuses on ensuring software quality through rigorous testing processes and methodologies. Participants will learn about test planning, execution, and automation to ensure software meets functional and non-functional requirements.
D63: SDLC | H63: Project Planning Tools | N63: Test Management and Documentation | R63: Software/Performance Testing Tools
D69: Agil and Scrum Methodologies | H69: Resource/Budget Management and Risk Management and Analysis | N69: CI/CD Tools | R69: Behavior-driven Development (BDD)
B79: PHASE 3 TRAINING - Retooling (Vendor Training)
C81: Business Analyst Deck | M81: SysDev Deck
C93: Project Manager Deck | M93: Quality Assurance

Sheet SSCGI_Training_Roadmap
B1: SSCGI TRANING ROADMAP
B2: SSCGI TRANING ROADMAP is a comprehesive pragmatic approach design to equip system devloper, business analyst, project manager and quality assurance aspirant with the indemand technical skills, business processes and management strategies. It follows a sequential approach and in phases to cater the diverses roles and specifications required by the client's need.
B5: Each phase comprises structured sections that build on foundational knowledge while progressively introducing advanced tools and techniques.
B7: Training Roadmap Objectives:
B8: 1. Train the participants to design and deliver tailored IT solutions that aling wiht SSCGI's "We Designm You Decide" philosopy to empower customer-centric innovation
B9: 2. Equip participants with technical skills and professional standards to develop reliable, compliant IT solutions
B10: 3. Cultivate teamwork, adaptability and leaderships to produce professionals who contribute to SSCGI's mission and economic development
B11: 4. Prepare the participants with skills and an entrepreneurial mindset to support SSCGI's vision of becoming a global leader in IT solutions.
B13: PHASE 1 TRAINING
B14: The Training Roadmap – Phase 1 is a 120-hour program covering onboarding, RDBMS, data warehousing, and ETL using Azure. It concludes with a Revalida, and project where participants apply their skills to deliver a practical, integrated solution.
B33: The Training Roadmap – Phase 2 is a 120-hour program covering on key methodologies and tools in software development and project managentated solution. The goal is to provide learners with an understanding in SDLC and Scrum frameworks and how effectively utilize project management tools for tracking and delivering projects

Sheet SkillsRoadmap
B1: SSCGI TRAINING BOOTCAMP
B2: Phase | C2: SID | D2: Tasks | F2: Man Hours | H2: Modularity | I2: Status | J2: Assessment | L2: Remarks
B3: 1 | C3: 1 | D3: Working Environments and Tools | F3: =SUM(F4:F7) -> 44 | I3: Completed
D4: Command-line Essentials | F4: 4 | H4: Udemy | I4: Completed
D5: Intro to Git | F5: 4 | H5: Udemy | I5: Completed
D6: HTML Guide | F6: 6 | H6: Udemy | I6: Completed
D7: Responsive HTML and CSS | F7: 30 | H7: Udemy | I7: Completed
C8: 2 | D8: Responsive Simple Web App | F8: =SUM(F9:F13) -> 40 | I8: Completed
D9: Responsive HTML and CSS | F9: 10 | H9: Udemy | I9: Completed
D10: Bootstrap | F10: 14 | H10: Udemy | I10: Completed
D11: JavaScript Basics for Beginners | F11: 8 | H11: Udemy | I11: Completed
D12: JQuery | F12: 4 | H12: Udemy | I12: Completed
D13: Ajax Development | F13: 4 | H13: Udemy | I13: Completed | J13: Assessment: Technical Exam
C14: s03 | D14: Review - HTML and Bootstrap | F14: 4 | H14: Classroom Type | I14: Completed | J14: Hands-on activity - Developer Profile
C15: s04 | D15: Review - JavaScript Functions and conditional structures | F15: 4 | H15: Classroom Type | I15: Completed | J15: Hands-on activity - Pasaload App planning and prototype
C16: s05 | D16: JavaScript - Arrays and Array Manipulation | F16: 4 | H16: Classroom Type | I16: Completed | J16: Hands-on activity - Pasaload App with verification
C17: s06 | D17: JavaScript - Introduction to JSON and JavaScript Object Notation | F17: 4 | H17: Classroom Type | I17: In Progress | J17: Hands-on activity - Creating and apply test plan for Pasaload Project
C18: s07 | D18: JavaScript - OOP | F18: 4 | H18: Classroom Type | I18: Not Started Yet | J18: Hands-on activity
C19: s08 | D19: JavaScript - ES6 Updates | F19: 4 | H19: Classroom Type | I19: Not Started Yet | J19: Hands-on activity
D20: RDBMS and Structured Query Language | F20: =SUM(F21:F30) -> 40 | I20: Not Started Yet | J20: Assessment: Technical Exam
C21: s09 | D21: MSSQL - Intro to RDBMS and Database Design | F21: 4 | G21: 45628 | H21: Classroom Type | I21: Not Started Yet | J21: Hands-on activity
C22: s10 | D22: MSSQL - Relational Schema | F22: 4 | G22: 45628 | H22: Classroom Type | I22: Not Started Yet | J22: Hands-on activity
C23: s11 | D23: MSSQL - Data Modeling and Transition | F23: 4 | G23: 45629 | H23: Classroom Type | I23: Not Started Yet | J23: Hands-on activity
C24: s12 | D24: MSSQL - SQL Basics | F24: 4 | G24: 45629 | H24: Classroom Type | I24: Not Started Yet | J24: Hands-on activity
C25: s13 | D25: MSSQL - CRUD Operations | F25: 4 | G25: 45630 | H25: Classroom Type | I25: Not Started Yet | J25: Hands-on activity
C26: s14 | D26: MSSQL - Aggregation and Query Case Studies | F26: 4 | G26: 45630 | H26: Classroom Type | I26: Not Started Yet | J26: Hands-on activity
C27: s15 | D27: MSSQL - Query Optimization | F27: 4 | G27: 45631 | H27: Classroom Type | I27: Not Started Yet | J27: Hands-on activity
